Workbook

Sheet 廣交會
A1: SKU | B1: Description | C1: Location | D1: L | E1: W | F1: H | G1: FOB | H1: Unit | I1: Carton Qty | J1: Note | K1: IMG | L1: Keyword
A2: WU77683AP | B2: Lycanthrope Werewolf Moon Howl | C2: CF | D2: 5.5 | E2: 3 | F2: 8.3 | G2: 2.1 | H2: PC | I2: 1 | J2: WU | K2: https://d2smnk90fd10gg.cloudfront.net/commodity/photo/WU77683AP-1.jpg | L2: Wolves; Gothic Designs; Greek & Roman MythologyFantasy creature; Bronze; Mythological symbolism; Fantasy; Standing; Mythical; Halloween; Round base; Howling; Gothic; Werewolf; Lycanthrope; Moon Howl; Supernatural lore; Werewolf: The Apocalypse; Underworld; Greek gods, Greek goddesses, Roman gods, Roman goddesses,
A3: WU78064AP | B3: Alexander The Great | C3: CF | D3: 4.5 | E3: 4 | F3: 9.3 | G3: 2 | H3: PC | I3: 1 | J3: WU | K3: https://d2smnk90fd10gg.cloudfront.net/commodity/photo/WU78064AP-1.jpg | L3: Knights & Warriors; Greek & Roman Mythology; Warrior; MiniaturesBronze; Classical; Greek; Human form; Brown; Standing; Gold; Sword; Warrior; Historical figure; King; Rectangular base; Ruler; Armor; Helmet; Hellenistic; General; alexander the great; - Occupation if any:; Greek gods, Greek goddesses, Roman gods, Roman goddesses,
A4: WU78062AP | B4: Leonidas | C4: CF | D4: 6.5 | E4: 4 | F4: 7.7 | G4: 2.2 | H4: PC | I4: 1 | J4: WU | K4: https://d2smnk90fd10gg.cloudfront.net/commodity/photo/WU78062AP-1.JPG | L4: Knights & Warriors; Greek & Roman Mythology; Warrior; MiniaturesGreek gods, Greek goddesses, Roman gods, Roman goddesses,
A5: WU78350AA | B5: Crusader Knight Axe And Shield | C5: CF | D5: 3.5 | E5: 2.5 | F5: 8 | G5: 2.2 | H5: PC | I5: 1 | J5: WU | K5: https://d2smnk90fd10gg.cloudfront.net/commodity/photo/WU78350AA-1.jpg | L5: Knights & Warriors; MiniaturesRectangular; Classical; Black; Standing; Religious symbols; Gold; Silver; Medieval; Knight; Shield; Warrior; Christianity; Historical; Axe; Crusader; Medieval soldier; Templar
A6: WU78351AA | B6: German Ceremonial Knight Armor Sword Stance | C6: CF | D6: 3.5 | E6: 2.5 | F6: 8 | G6: 2.2 | H6: PC | I6: 1 | J6: WU | K6: https://d2smnk90fd10gg.cloudfront.net/commodity/photo/WU78351AA-1.jpg | L6: Knights & Warriors; MiniaturesClassical; Human figure; Standing; Gold; Silver; Medieval; Knight; Sword; Warrior; Steel; Armor; Chivalry; German; Sword Stance
A7: WU78353AA | B7: Medieval Knight Armor Sword Stance | C7: CF | D7: 3.5 | E7: 2.5 | F7: 8 | G7: 2.2 | H7: PC | I7: 1 | J7: WU | K7: https://d2smnk90fd10gg.cloudfront.net/commodity/photo/WU78353AA-1.jpg | L7: Knights & Warriors; MiniaturesClassical; Human form; Standing; Gold; Realistic; Silver; Medieval; Knight; Sword; Warrior; Steel; Armor; Historical; Medieval Knight; Helmeted Head; Chivalry; Armored figure; Base pedestal; Feudal; European history; Black (base); Paladin; Noble knight
A8: WU78354AA | B8: Medieval Knight Armor Sword Stance | C8: CF | D8: 3.5 | E8: 2.5 | F8: 8 | G8: 2.2 | H8: PC | I8: 1 | J8: WU | K8: https://d2smnk90fd10gg.cloudfront.net/commodity/photo/WU78354AA-1.jpg | L8: Knights & Warriors; MiniaturesHuman figure; Standing; Realistic; Medieval; Gunmetal black; Knight; Sword; Warrior; Gold accents; Soldier; Steel; Historical; Medieval Knight; European heritage; Standing base
A9: WU78117AA | B9: Sapphire Plume Peacock Wand | C9: JH | D9: 2.5 | E9: 2.5 | F9: 36 | G9: 2.4 | H9: PC | I9: 1 | J9: WU | K9: https://d2smnk90fd10gg.cloudfront.net/commodity/photo/WU78117AA-1.jpg | L9: Peacock; WiccaFantasy creature; Green; Mythological symbolism; Fantasy; Decorative; Blue; Brown; Harry Potter; Plume; Sapphire; Wand; Peacock symbolism; Wicca, wicca goddesses, wicca gods
A10: WU78118AA | B10: Owl Wand | C10: JH | D10: 2.5 | E10: 2 | F10: 36.5 | G10: 2.4 | H10: PC | I10: 1 | J10: WU | K10: https://d2smnk90fd10gg.cloudfront.net/commodity/photo/WU78118AA-1.jpg | L10: Owl; WiccaFantasy creature; Mythological symbolism; Round; Fantasy; Brown; Harry Potter; Wood; Wildlife animal; Wand; Wicca, wicca goddesses, wicca gods
A11: WU78392AP | B11: Archangel Saint Gabriel Blowing Trumpet | C11: CF | D11: 5.5 | E11: 5 | F11: 10 | G11: 2.5 | H11: PC | I11: 1 | J11: WU | K11: https://d2smnk90fd10gg.cloudfront.net/commodity/photo/WU78392AP-1.jpg | L11: Religious; AngelBronze; Classical; Standing; Metallic; Flowers; Religious symbols; Baroque; Gold; Winged; Christmas; Religious figure; Christian symbolism; Angelic symbolism; Trumpet; Archangel; Trumpet; Saint; Blowing trumpet; Divine messenger
A12: WU77707AA | B12: Vampire Count | C12: JH | D12: 6 | E12: 4 | F12: 11.5 | G12: 2.7 | H12: PC | I12: 1 | J12: WU | K12: https://d2smnk90fd10gg.cloudfront.net/commodity/photo/WU77707AA-1.jpg | L12: Gothic DesignsFantasy creature; Mythological symbolism; White; Black; Standing; Red; Gothic; Halloween; Vampire; Dracula; Nosferatu; Castlevania; Horror; Cape; Menacing
A13: WU78189AA | B13: French Bulldog Chat Room Menace | C13: CF | D13: 4.5 | E13: 6 | F13: 7.5 | G13: 2.7 | H13: PC | I13: 1 | J13: WU | K13: https://d2smnk90fd10gg.cloudfront.net/commodity/photo/WU78189AA-1.jpg | L13: Dogsfrench bulldog; Dog, Dogs, Puppy, Hound
... A23: WU77618AA | B23: Green Man Summer Berry Wall Plaque | C23: CF | D23: 14.5 | E23: 2 | F23: 9.5 | G23: 3.9 | H23: PC | I23: 1 | J23: WU | K23: https://d2smnk90fd10gg.cloudfront.net/commodity/photo/WU77618AA-1.jpg | L23: Celtic Design & Myths; Wall Plaques; Norse Myth; WiccaFantasy creature; Green; Mythological symbolism; Decorative; Classical; Nature; Brown; Nature-inspired; Leafy; Norse mythology, Norse gods, Norse goddesses, Nordic gods; Triangular; Earth tones; Nature spirit; Green Man; Pagan symbolism; Celtic design, Celtic gods, Celtic deities嚗eltic goddesses; Wicca, wicca goddesses, wicca gods
A24: WU77619AA | B24: Green Man Spring Mushroom Wall Plaque | C24: CF | D24: 14.5 | E24: 2 | F24: 10 | G24: 3.9 | H24: PC | I24: 1 | J24: WU | K24: #N/A | L24: #N/A
A25: WU78190AA | B25: Pug | C25: CF | D25: 12 | E25: 6 | F25: 9.5 | G25: 3.9 | H25: PC | I25: 1 | J25: WU | K25: https://d2smnk90fd10gg.cloudfront.net/commodity/photo/WU78190AA-1.jpg | L25: DogsDog, Dogs, Puppy, Hound
A26: WU78376AP | B26: Santa Muerte Seating On Throne Holding Scythe And Scale | C26: CF | D26: 5 | E26: 4.6 | F26: 8.4 | G26: 3.9 | H26: PC | I26: 1 | J26: WU | K26: https://d2smnk90fd10gg.cloudfront.net/commodity/photo/WU78376AP-1.jpg | L26: Skeleton, Skull, Grimreaper, Zombie; WiccaGoddess; Bronze; Brown; Religious symbols; Gold; Halloween; Scythe; Religious art; Throne; Gothic; Scale; Mexican Folk Religion; Santa Muerte; Seated; Our Lady of Holy Death; Human Skull
A27: WU78267AP | B27: Zeus Greek God Of The Sky Holding Thunderbolt With Eagle | C27: CF | D27: 7.5 | E27: 5 | F27: 11 | G27: 3.95 | H27: PC | I27: 1 | J27: WU | K27: https://d2smnk90fd10gg.cloudfront.net/commodity/photo/WU78267AP-1.jpg | L27: Greek & Roman Mythologygreek mythology; Ancient Greek; Cloud; Eagle, Falcon, Hawk; Lighting, Thunder, Thunderbolt; Zeus; Greek gods, Greek goddesses, Roman gods, Roman goddesses,
A28: WU77828A1 | B28: Triple Goddess Tealight Candle Holder | C28: JH | D28: 9 | E28: 7 | F28: 3.5 | G28: 4 | H28: PC | I28: 1 | J28: WU | K28: https://d2smnk90fd10gg.cloudfront.net/commodity/photo/WU77828A1-1.jpg | L28: Celtic Design & Myths; Candle, Incense and Oil Burner; WiccaGoddess; Bronze; Contemporary; Round; Candle holder; Wicca; Celtic; Mythological; Triple goddess; Pagan symbolism; Crescent; Pentacle; Celtic design, Celtic gods, Celtic deities嚗eltic goddesses; Wicca, wicca goddesses, wicca gods
A29: WU77846AA | B29: Triple Black Cat Candle Tea Light Holder | C29: JH | D29: 10 | E29: 10 | F29: 5 | G29: 4 | H29: PC | I29: 1 | J29: WU | K29: https://d2smnk90fd10gg.cloudfront.net/commodity/photo/WU77846AA-1.jpg | L29: Cats; Candle, Incense and Oil Burner; WiccaCat, Cats, Kitty, Kitten, Kitties; Feline figure; Kitty; Feline; Cats, Cat, Kitten, Kitty; Wicca, wicca goddesses, wicca gods
A30: WU78173AB | B30: Infant Jesus With Golden Halo | C30: JH | D30: 13.5 | E30: 4.5 | F30: 3.5 | G30: 4.3 | H30: PC | I30: 1 | J30: WU | K30: #N/A | L30: #N/A
A31: WU78232AP | B31: Hector Of Troy | C31: CF | D31: 7.5 | E31: 6 | F31: 9.5 | G31: 4.3 | H31: PC | I31: 1 | J31: WU | K31: #N/A | L31: #N/A
A32: WU78233AP | B32: Achilleus Hero Of Trojan War | C32: CF | D32: 7.8 | E32: 5 | F32: 9.5 | G32: 4.3 | H32: PC | I32: 1 | J32: WU | K32: #N/A | L32: #N/A
A33: WU78479AP | B33: Greenman Lady Of Abundance Wall Plaque | C33: CF | D33: 13.5 | E33: 14.5 | F33: 3 | G33: 4.4 | H33: PC | I33: 1 | J33: WU | K33: https://d2smnk90fd10gg.cloudfront.net/commodity/photo/WU78479AP-1.jpg | L33: Celtic Design & Myths; Home Accent; Wall Plaques; Wicca; Miniaturesartistic; Fantasy creature; Goddess; Bronze; Green; Mythological symbolism; Round; Nature; Mythical; Multicolored; Leaves; Berries; Autumn; Nature spirit
A34: WU78183A4 | B34: Yoga Elephant Headstand | C34: JH | D34: 8 | E34: 7 | F34: 9 | G34: 4.6 | H34: PC | I34: 1 | J34: WU | K34: https://d2smnk90fd10gg.cloudfront.net/commodity/photo/WU78183A4-1.jpg | L34: Yoga, Performance Art and Dance; ElephantBronze; Contemporary; Round; Purple; Yoga; Trunk; Elephant; Wildlife animal; Meditation; Inverted; Legs; Headstand
A35: WU78193A4 | B35: French Bulldog Food Delivery Carrier | C35: CF | D35: 4.5 | E35: 8 | F35: 9 | G35: 4.8 | H35: PC | I35: 1 | J35: WU | K35: https://d2smnk90fd10gg.cloudfront.net/commodity/photo/WU78193A4-1.jpg | L35: Dogsfrench bulldog; Dog, Dogs, Puppy, Hound
A36: WU77808A1 | B36: Spiral Goddess Triple Moon Tealight Candle Holder | C36: JH | D36: 7 | E36: 7 | F36: 12 | G36: 5 | H36: PC | I36: 1 | J36: WU | K36: https://d2smnk90fd10gg.cloudfront.net/commodity/photo/WU77808A1-1.jpg | L36: Celtic Design & Myths; Candle, Incense and Oil Burner; WiccaFantasy creature; Goddess; Bronze; Mythological symbolism; Contemporary; Round; Abstract; Standing; Spiral; Religious symbols; Tealight holder; Celtic design, Celtic gods, Celtic deities嚗eltic goddesses; Wicca, wicca goddesses, wicca gods
A37: WU78251AP | B37: See Hear Speak No Evil Skull Pen Holder | C37: JH | D37: 11.5 | E37: 11.5 | F37: 10 | G37: 5 | H37: PC | I37: 1 | J37: WU | K37: https://d2smnk90fd10gg.cloudfront.net/commodity/photo/WU78251AP-1.jpg | L37: Gothic Designs; Skeleton, Skull, Grimreaper, Zombie; Vase and Vessel; Studies DecorSkull; Human skull; Skeleton; See No Evil; Hear No Evil; Three Wise Monkeys
A38: WU78277AA | B38: Our Lady Of Fatima | C38: CF | D38: 5.5 | E38: 4.5 | F38: 15.5 | G38: 5 | H38: PC | I38: 1 | J38: WU | K38: https://d2smnk90fd10gg.cloudfront.net/commodity/photo/WU78277AA-1.jpg | L38: Mary, Mother of JesusWhite; Gold; Crown; Mary; Blessed Virgin Mary; Mother Mary
A39: WU78280AA | B39: The Immaculate Heart Of Mary | C39: CF | D39: 5 | E39: 5 | F39: 15.5 | G39: 5 | H39: PC | I39: 1 | J39: WU | K39: https://d2smnk90fd10gg.cloudfront.net/commodity/photo/WU78280AA-1.jpg | L39: Mary, Mother of JesusWhite; Blue; Religious; Mary; Blessed Virgin Mary; Mother Mary
A40: WU78186AA | B40: The Wardens Of The Damned Pen Holder | C40: JH | D40: 12 | E40: 10.5 | F40: 12.5 | G40: 5.2 | H40: PC | I40: 1 | J40: WU | K40: https://d2smnk90fd10gg.cloudfront.net/commodity/photo/WU78186AA-1.jpg | L40: Skeleton, Skull, Grimreaper, Zombie; Vase and Vessel; Studies DecorFantasy creature; Mythological symbolism; Fantasy; Rectangular; Standing; Gothic; Halloween; Game of Thrones; Gunmetal black; Grim Reaper; Staff; Skeleton; Stone grey; Tower; Medieval; Dark Souls; Diablo; Warden; Fortress; Hooded cloak
A41: WU77634A4 | B41: Hear No Evil Viking | C41: JH | D41: 8.8 | E41: 8 | F41: 10 | G41: 5.3 | H41: PC | I41: 1 | J41: WU | K41: https://d2smnk90fd10gg.cloudfront.net/commodity/photo/WU77634A4-1.jpg | L41: Knights & Warriors; Norse MythNorse mythology, Norse gods, Norse goddesses, Nordic gods; Humanoid figures; See No Evil; Hear No Evil; Speak No Evil; Three Wise Monkeys; Trio; Covering ears, eyes, mouth; Vikings; Viking
A42: WU77635A4 | B42: See No Evil Viking | C42: CF | D42: 8.5 | E42: 7.5 | F42: 10 | G42: 5.3 | H42: PC | I42: 1 | J42: WU | K42: https://d2smnk90fd10gg.cloudfront.net/commodity/photo/WU77635A4-1.jpg | L42: Knights & Warriors; Norse MythNorse mythology, Norse gods, Norse goddesses, Nordic gods; See No Evil; Hear No Evil; Speak No Evil; Three Wise Monkeys; Trio; Covering ears, eyes, mouth; Vikings; Viking
A43: WU77636A4 | B43: Speak No Evil Viking | C43: CF | D43: 9 | E43: 7 | F43: 10 | G43: 5.3 | H43: PC | I43: 1 | J43: WU | K43: https://d2smnk90fd10gg.cloudfront.net/commodity/photo/WU77636A4-1.jpg | L43: Knights & Warriors; Norse MythNorse mythology, Norse gods, Norse goddesses, Nordic gods; Scandinavian; Vikings (TV Series); Humanoid figures; See No Evil; Hear No Evil; Speak No Evil; Three Wise Monkeys; Trio; Covering ears, eyes, mouth; Vikings; Viking
A44: WU78274AA | B44: Jesus Christ Divine Mercy | C44: CF | D44: 5.5 | E44: 6.5 | F44: 16 | G44: 5.4 | H44: PC | I44: 1 | J44: WU | K44: https://d2smnk90fd10gg.cloudfront.net/commodity/photo/WU78274AA-1.jpg | L44: Gospel of Jesus, Christ, Son of GodBlue; Red; Jesus; Off-white
... A55: WU78363AA | B55: Cardinal Bird Couple Perching On Snowy Branch | C55: CF | D55: 9 | E55: 7 | F55: 15.5 | G55: 6.6 | H55: PC | I55: 1 | J55: WU | K55: https://d2smnk90fd10gg.cloudfront.net/commodity/photo/WU78363AA-1.jpg | L55: Animal; BirdGreen; White; Brown; Nature-inspired; Realistic; Red; Christmas; Branch; Perching; Berries; Round base; Winter; Snow; Wildlife animal; Branch; Cardinal birds; Northern Cardinals
A56: WU78132AA1 | B56: Hail Mary Prayer Photo Frame | C56: CF | D56: 12 | E56: 3 | F56: 19 | G56: 6.8 | H56: PC | I56: 1 | J56: WU | K56: #N/A | L56: #N/A
A57: WU77621A4 | B57: Battling Crusader Hinged Trinket Chest | C57: JH | D57: 11.8 | E57: 7.5 | F57: 5.8 | G57: 7 | H57: PC | I57: 1 | J57: WU | K57: https://d2smnk90fd10gg.cloudfront.net/commodity/photo/WU77621A4-1.jpg | L57: Knights & Warriors; Trinket BoxBronze; Rectangular; Religious symbols; Silver; Gunmetal black; Knight; Sword; Shield; Riding; Warrior; Historical figure; Historical; Crusader; Medieval
A58: WU78272AA | B58: Saint Francis Of Assisi | C58: CF | D58: 9 | E58: 6.5 | F58: 15.5 | G58: 7 | H58: PC | I58: 1 | J58: WU | K58: https://d2smnk90fd10gg.cloudfront.net/commodity/photo/WU78272AA-1.jpg | L58: SaintsBrown; Dove; Cross; Monk; Catholic iconography; Deer
A59: WU78400AA | B59: Crouching Gargoyle | C59: JH | D59: 11.5 | E59: 12 | F59: 14.5 | G59: 7 | H59: PC | I59: 1 | J59: WU | K59: https://d2smnk90fd10gg.cloudfront.net/commodity/photo/WU78400AA-1.jpg | L59: Myth & Legend; Gothic DesignsFantasy creature; Crouching; Pedestal; Grey; ; - Alternative Names if any:; Wings; Protector; Guardian; Gothic; Halloween; Stone; Gargoyle; Charcoal; Medieval; ; - Shape or Elements:; Rectangular Base; Gothic; Winged; Crouching; Gargoyles (TV series); Demon statue; Stone guardian; Crouching; Architectural; Snarling
...

Sheet Sheet6
A1: sku | B1: tags_names | C1: photos
A2: WU78629AP | B2: Bronze; Mythological symbolism; Classical; Greek; Standing; Gold; Warrior; Realism; Bow; Figurative; Bow; Arrow; King; Ulysses; The Odyssey; Odysseus; Drawing bow; Dog (Argos); Ithacan King; Heroic | C2: https://d2smnk90fd10gg.cloudfront.net/commodity/photo/WU78629AP-1.jpg
A3: WU78618A4 | B3: Fantasy creature; Bronze; Mythological symbolism; Curved; Standing; Metallic; Organic; Fox; Wildlife animal; Celtic; Mythological; ; - Poses or Actions:; Celtic art; Drawing bow; Seated | C3: https://d2smnk90fd10gg.cloudfront.net/commodity/photo/WU78618A4-1.jpg
A4: WU78615A4 | B4: Bronze; Mythological symbolism; Contemporary; Blue; Nautical; Flowing Water; Jumping; Wildlife animal; Celtic; Waves; Celtic art; Humpback Whale; Knotwork | C4: https://d2smnk90fd10gg.cloudfront.net/commodity/photo/WU78615A4-1.jpg
A5: WU78609A4 | B5: Fantasy creature; Bronze; Green; Mythological symbolism; Round; Modern; Nautical; Halloween; Gunmetal black; Gothic; Tentacles; Lovecraftian; Mythological being; Cthulhu; Great Old One; Tankard; H.P. Lovecraft works | C5: https://d2smnk90fd10gg.cloudfront.net/commodity/photo/WU78609A4-1.jpg
A6: WU78604AP | B6: Fantasy creature; Bronze; Green; Mythological symbolism; Rectangular; Mythical; Nautical; Halloween; Gunmetal black; Lovecraftian; Cthulhu; Cthulhu Mythos | C6: https://d2smnk90fd10gg.cloudfront.net/commodity/photo/WU78604AP-1.jpg
A7: WU78605A4 | B7: Goddess; Bronze; Mythological symbolism; Classical; Greek; Standing; Metallic; Winged; Warrior; Earth tones; Percy Jackson; Horses; Trumpet; Chariot; Chariot; Winged Victory; Holding trumpet | C7: https://d2smnk90fd10gg.cloudfront.net/commodity/photo/WU78605A4-1.jpg
A8: WU78626A4 | B8: Bronze; Green; Classical; Brown; Standing; Red; Shield; Warrior; Historical figure; Mother; Circular base; Armor; Historical; Rome; Leader; Spear; Celtic; Historical symbolism; Boadicea; Boudicca; Marching | C8: https://d2smnk90fd10gg.cloudfront.net/commodity/photo/WU78626A4-1.jpg
A9: WU78624A4 | B9: Fantasy creature; Bronze; Mythological symbolism; Classical; Greek; Metallic; Warrior; Bow; Dynamic; Earth tones; Rearing; Mythological art; Archer; Centaur; Arrow; Bow and arrow; Drawing bow | C9: https://d2smnk90fd10gg.cloudfront.net/commodity/photo/WU78624A4-1.jpg
A10: WU78616A4 | B10: Bronze; Round; Classical; Floral; Religious symbols; Baroque; Gold; Lid; Angel; Rose; Wings; Cherub; Silver; Angelic symbolism; Urn; Seated; Guardian Angel Urn; Winged cherub | C10: https://d2smnk90fd10gg.cloudfront.net/commodity/photo/WU78616A4-1.jpg
A11: WU78614A4 | B11: Bronze; Classical; Metallic; Religious symbols; Renaissance; Religious figure; Cross; Jesus; Christian symbolism; Round base; Mary; La Pietà; Patina; Seated | C11: https://d2smnk90fd10gg.cloudfront.net/commodity/photo/WU78614A4-1.jpg
A12: WU78606A4 | B12: Bronze; Mythological symbolism; Classical; Greek; Standing; Mythological figure; Gold; Nautical; Waves; God; Percy Jackson; Trident; Poseidon; Neptune; God of War; Water deity | C12: https://d2smnk90fd10gg.cloudfront.net/commodity/photo/WU78606A4-1.jpg
... A47: WU78523A4 | B47: Bronze; Mythological symbolism; Round; Classical; Greek; Standing; Sword; Shield; Warrior; Historical figure; Marble; Ancient; Ancient Greece; Clash of the Titans; Mythological art; Sword; Mythological hero; Greek hero; Hero; Classical hues; Head of Medusa (element); Medusa's head; Triumphant pose | C47: https://d2smnk90fd10gg.cloudfront.net/commodity/photo/WU78523A4-1.jpg
A48: WU78503AA | C48: https://d2smnk90fd10gg.cloudfront.net/commodity/photo/WU78503AA-1.jpg
A49: WU73129BA | B49: Goddess; Bronze; Classical; Standing; Gold; Embracing; Sword; Shield; God; Love; Marble; Classical symbolism; Mythological figures; Renaissance; Mythological; Roman mythology; War | C49: https://d2smnk90fd10gg.cloudfront.net/commodity/photo/WU73129BA-1.jpg
A50: WU70783BA | B50: Mythological symbolism; Classical; Greek; Religious symbols; Gold; ; - Alternative Names if any:; God; Marble; Scepter; Percy Jackson; Clash of the Titans; Zeus; Throne; Seated | C50: https://d2smnk90fd10gg.cloudfront.net/commodity/photo/WU70783BA-1.jpg
A51: WU78610A4 | B51: Fantasy creature; Mythological symbolism; Contemporary; White; Standing; Maiden; - Alternative Names if any:; Gothic; Halloween; Gunmetal black; Marble; Skeleton; - Cultural or Symbolic Elements:; Memento Mori | C51: https://d2smnk90fd10gg.cloudfront.net/commodity/photo/WU78610A4-1.JPG
A52: WU78599A4 | B52: mythological; Goddess; Sea deity; Ocean symbolism; Inuit deity; Inuit mythology | C52: https://d2smnk90fd10gg.cloudfront.net/commodity/photo/WU78599A4-1.JPG
A53: WU78595A4 | B53: Bronze; Mythological symbolism; Curved; Nautical; Traditional; Dragon; Warrior; Wood; Long; Gliding; Historical; Drakkar; Norse; Scandinavian; Sail; Shields; Vikings (TV Series); Assassin's Creed Valhalla; How to Train Your Dragon; Off-white; Longship; Sailing; Navigator; Viking; Dragon Head; Explorer; Boat; Metallic silver; The Last Kingdom; Seafarer; Viking Age; Oar; Clan; Nordic Blue; Narrow; Hull; Craftsmanship; Mast; Navigating; Northmen; Shipbuilder; Snekke; Longship Display; Viking Tray; Nordic Vessel | C53: https://d2smnk90fd10gg.cloudfront.net/commodity/photo/WU78595A4-1.jpg
A54: WU78587VA | B54: Bronze; Contemporary; White; Rectangular; Resting; Realistic; Lying down; Wood; Wildlife animal; Dog; Cocker Spaniel; Curved edges; Spaniel Urn; Cocker Urn; Pet Memorial Urn; Pet Memorial; Grief Symbol | C54: https://d2smnk90fd10gg.cloudfront.net/commodity/photo/WU78587VA-1.JPG
A55: WU78583AA | B55: Rectangular; Religious symbols; Gold; Christmas; Gothic; Medieval; Christianity; Marble; Stone; Saints; The Da Vinci Code; Cathedral; Tower-like; Church Miniature; Religious Display; Cathedrals | C55: https://d2smnk90fd10gg.cloudfront.net/commodity/photo/WU78583AA-1.JPG
A56: WU78582BA | B56: Green; Contemporary; White; Decorative; Pastel; Pink; Floral; Spring; Petal; Nature-inspired; Bloom; Charm; Blossom | C56: https://d2smnk90fd10gg.cloudfront.net/commodity/photo/WU78582BA-1.JPG
A57: WU78582A4 | B57: Pastel; Floral; Curved; Petal; - Alternative Names if any:; Soft tones; Floral form; Charm; Petal color; Charm color; Delicate shape | C57: https://d2smnk90fd10gg.cloudfront.net/commodity/photo/WU78582A4-1.JPG
A58: WU78578BA | B58: Goddess; Mythological symbolism; White; Classical; Pastel; Floral; Greek; Modern; Human figure; Curved; Petal; Standing; Flowing; Romanticism; Graceful; - Alternative Names if any:; Victorian; Marble; - Movie, book, anime, manga, game titles that shares the same th; Floral form; - Shape or Elements:; - Style or Artistic Influence:; - Poses or Actions:; Charm; Mythical being; - Seasonal attribute if any:; Delicate shape; Rose gold; Victorian elegance | C58: https://d2smnk90fd10gg.cloudfront.net/commodity/photo/WU78578BA-1.JPG
A59: WU78578A4 | B59: Fantasy creature; Goddess; Bronze; Contemporary; White; Classical; Standing; Elegant; Graceful; - Alternative Names if any:; Marble; - Objects if any:; - Poses or Actions:; - Seasonal attribute if any: | C59: https://d2smnk90fd10gg.cloudfront.net/commodity/photo/WU78578A4-1.JPG
A60: WU75343BA | B60: Goddess; Mythological symbolism; White; Classical; Greek; Standing; Ivory; Historical figure; Youth; Marble; Greek mythology; Hebe; divine youth | C60: https://d2smnk90fd10gg.cloudfront.net/commodity/photo/WU75343BA-1.JPG
... A110: WU78536AA | B110: Fantasy creature; Green; Mythological symbolism; Face; Fantasy; Brown; Nature-inspired; Oval; Halloween; Wall-mounted; Wood; Mystical; The Witcher; Lord of the Rings; Earthy tones; Tree spirit; Forest guardian; Tree Man; Woodland spirit; Nature warden; Nature connection; Druidic symbolism | C110: https://d2smnk90fd10gg.cloudfront.net/commodity/photo/WU78536AA-1.jpg
A111: WU78535AA | C111: https://d2smnk90fd10gg.cloudfront.net/commodity/photo/WU78535AA-1.jpg
A112: WU78528AA | B112: Bronze; Nautical; Shield; Warrior; Wood; Historical; Viking ship; Drakkar; Norse; Vikings (TV Series); Assassin's Creed Valhalla; Longship; Viking; Boat; Sailor; Viking Longship; Norse ship; Oar | C112: https://d2smnk90fd10gg.cloudfront.net/commodity/photo/WU78528AA-1.jpg
A113: WU78521AA | B113: Contemporary; Curved; Organic; Minimalist; Fluid; Soft White; Serene Blue; Gentle Pink | C113: https://d2smnk90fd10gg.cloudfront.net/commodity/photo/WU78521AA-1.jpg
A114: WU78512AA | B114: Fantasy creature; Mythological symbolism; White; Classical; Standing; Religious symbols; Baroque; Gold; Winged; Angel; - Alternative Names if any:; Flying; Halo; - Colors or Color Mapping:; - Shape or Elements:; - Style or Artistic Influence:; - Objects if any:; - Poses or Actions:; - Seasonal attribute if any:; Soft White; Serene Blue; Gentle Pink; Celestial Companions; Divine Allies | C114: https://d2smnk90fd10gg.cloudfront.net/commodity/photo/WU78512AA-1.JPG
A115: WU78508A4 | B115: mythological; Fantasy creature; Mythological symbolism; Round; Trinket box; Circular; Traditional; Wood; Stone; Norse; Vikings; Viking; Mythical animal; God of War; Runes; Wolf Trinket Box; Norse Wolf Box | C115: https://d2smnk90fd10gg.cloudfront.net/commodity/photo/WU78508A4-1.jpg
A116: WU78346YA | B116: Contemporary; White; Lying; Realism; Running; Horses; Strength; Freedom; Wildlife animal; Prancing; Wild nature | C116: https://d2smnk90fd10gg.cloudfront.net/commodity/photo/WU78346YA-1.jpg
A117: WU78538A4 | B117: mythological; Goddess; Bronze; Green; Mythological symbolism; Classical; Standing; Mythological figure; - Alternative Names if any:; Triangular; Tree; Earth tones; Triple Goddess; Pagan symbolism; Feminine archetypes | C117: https://d2smnk90fd10gg.cloudfront.net/commodity/photo/WU78538A4-1.jpg
A118: WU78532A4 | B118: Bronze; Contemporary; Kneeling; Brown; Realistic; - Alternative Names if any:; Girl; Hugging; Blue accents; Puppy; Dog | C118: https://d2smnk90fd10gg.cloudfront.net/commodity/photo/WU78532A4-1.jpg
A119: WU78520A4 | B119: Bronze; Mythological symbolism; Classical; Greek; Mythological figure; Wings; Flying; Cloud; Ascending; Icarus | C119: https://d2smnk90fd10gg.cloudfront.net/commodity/photo/WU78520A4-1.jpg
A120: WU78518A4 | B120: mythological; Bronze; Green; Mythological symbolism; Classical; Blue; Human form; Standing; Gold; Flowing Water; Fish; water; God; Gesturing; Sumerian deity; Sumerian culture; Ea | C120: https://d2smnk90fd10gg.cloudfront.net/commodity/photo/WU78518A4-1.jpg
A121: WU78511AP | B121: mythological; Bronze; Green; Mythological symbolism; Round; Gold; Winged; Silver; Medieval; Shield; Warrior; Norse; Falcon; Axe; Viking; Twin Axe; Crossed; Spread Wings | C121: https://d2smnk90fd10gg.cloudfront.net/commodity/photo/WU78511AP-1.jpg
A122: WU78505A4 | B122: Bronze; Human figure; Standing; Multicolored; Religious symbols; Gold; Traditional; Crown; Owl; Religious; Roses; Death symbolism; Santa Muerte; Mexican; Saint of Death | C122: https://d2smnk90fd10gg.cloudfront.net/commodity/photo/WU78505A4-1.jpg
A123: WU78504AP | B123: Bronze; Mythological symbolism; Classical; Brown; Standing; Gold; Religious symbolism; Red; God; Round base; Torch; Celtic; Celtic deity; Holding torch | C123: https://d2smnk90fd10gg.cloudfront.net/commodity/photo/WU78504AP-2.jpg
...

Sheet Sheet5
A1: SKU | B1: TITLE | C1: L | D1: W | E1: H | F1: FOB | J1: Location
A2: AT09084A2 | B2: Hades God Of The Greek Underworld | C2: 5.5 | D2: 4.5 | E2: 11 | F2: 8.5 | G2: PC | H2: 24 | J2: =VLOOKUP(A2,'廣交會'!A:C,3,false) -> CF
A3: AT09085A4 | B3: Medusa The Gorgon Drawing The Bow | C3: 6.5 | D3: 4.5 | E3: 11.5 | F3: 8.3 | G3: PC | H3: 24 | I3: WU(IB.GR) | J3: =VLOOKUP(A3,'廣交會'!A:C,3,false) -> CF
A4: AT09086A2 | B4: Zeus Greek God Of The Sky | C4: 7.5 | D4: 5 | E4: 11 | F4: 8.5 | G4: PC | H4: 24 | J4: =VLOOKUP(A4,'廣交會'!A:C,3,false) -> CF
A5: AT09087A4 | B5: Athena Greek Goddess Of Wisdom And Warfare | C5: 9.5 | D5: 6 | E5: 10.5 | F5: 8.3 | G5: PC | H5: 24 | J5: =VLOOKUP(A5,'廣交會'!A:C,3,false) -> CF
A6: AT09088A4 | B6: Winged Nike Of Samothrace | C6: 5 | D6: 6.5 | E6: 10.5 | F6: 8.3 | G6: PC | H6: 24 | J6: =VLOOKUP(A6,'廣交會'!A:C,3,false) -> CF
A7: AT09089A4 | B7: Oceanus The Primordial Titan Of Water | C7: 7 | D7: 5.5 | E7: 10 | F7: 8.5 | G7: PC | H7: 24 | J7: =VLOOKUP(A7,'廣交會'!A:C,3,false) -> CF
A8: AT09093A2 | B8: Hippocrates Of Cos Holding Hippocratic Oath | C8: 5 | D8: 3 | E8: 11 | F8: 8.5 | G8: PC | H8: 48 | J8: =VLOOKUP(A8,'廣交會'!A:C,3,false) -> CF
A9: AT09094A2 | B9: La Justica | C9: 4 | D9: 4.5 | E9: 11 | F9: 8.5 | G9: PC | H9: 48 | J9: =VLOOKUP(A9,'廣交會'!A:C,3,false) -> CF
A10: WU73501A4 | B10: Guardian Angel Holding A Child And Flower (Mbz+Color) | C10: 20 | D10: 18 | E10: 27 | F10: 16.2 | G10: PC | H10: 4 | I10: WU | J10: =VLOOKUP(A10,'廣交會'!A:C,3,false) -> CF
A11: WU74800A4 | B11: Lion(Bronze) | C11: 34 | D11: 15 | E11: 26.5 | F11: 21 | G11: PC | H11: 1 | I11: WU | J11: =VLOOKUP(A11,'廣交會'!A:C,3,false) -> CF
A12: WU75168A4 | B12: Mozart | C12: 20.5 | D12: 14 | E12: 20 | F12: 22.2 | G12: PC | H12: 4 | I12: WU | J12: =VLOOKUP(A12,'廣交會'!A:C,3,false) -> CF
A13: WU75184AA | B13: King Cobra | C13: 32 | D13: 28.5 | E13: 33 | F13: 33 | G13: PC | H13: 1 | I13: WU | J13: =VLOOKUP(A13,'廣交會'!A:C,3,false) -> CF
A14: WU75218A4 | B14: St. Michael | C14: 16 | D14: 14 | E14: 28 | F14: 17.6 | G14: PC | H14: 6 | I14: WU | J14: =VLOOKUP(A14,'廣交會'!A:C,3,false) -> CF
A15: WU75321A4 | B15: Norse God - Freyr | C15: 20.5 | D15: 14.5 | E15: 28.5 | F15: 18.8 | G15: PC | H15: 4 | I15: WU | J15: =VLOOKUP(A15,'廣交會'!A:C,3,false) -> CF
A16: WU75357A4 | B16: Norse God – Odin | C16: 17 | D16: 12 | E16: 25 | F16: 17.5 | G16: PC | H16: 6 | I16: WU | J16: =VLOOKUP(A16,'廣交會'!A:C,3,false) -> CF
A17: WU75389AA | B17: Baby Zebra | C17: 15.7 | D17: 7.4 | E17: 17.5 | F17: 6.8 | G17: PC | H17: 24 | I17: WU | J17: =VLOOKUP(A17,'廣交會'!A:C,3,false) -> CF
A18: WU75452A4 | B18: Frederic Chopin | C18: 22 | D18: 16.5 | E18: 22 | F18: 23.5 | G18: PC | H18: 4 | I18: WU | J18: =VLOOKUP(A18,'廣交會'!A:C,3,false) -> CF
A19: WU75579AD | B19: Archangel Saint Michael Triumphs Over Evil | C19: 7.5 | D19: 3.5 | E19: 10.5 | F19: 3.2 | G19: PC | H19: 72 | I19: WU | J19: =VLOOKUP(A19,'廣交會'!A:C,3,false) -> CF
A20: WU75580AC | B20: Archangel Raphael Holding Spear And Shield | C20: 8.5 | D20: 4.5 | E20: 10 | F20: 3.2 | G20: PC | H20: 48 | I20: WU | J20: =VLOOKUP(A20,'廣交會'!A:C,3,false) -> CF
A21: WU75746AA | B21: White Wolf On Snowy Ground Looking Back | C21: 24 | D21: 15 | E21: 23.5 | F21: 12.6 | G21: PC | H21: 4 | I21: WU | J21: =VLOOKUP(A21,'廣交會'!A:C,3,false) -> CF
A22: WU75920A4 | B22: The Last Supper (Mbz+Color) | C22: 31.5 | D22: 6.5 | E22: 12 | F22: 19.2 | G22: PC | H22: 8 | J22: =VLOOKUP(A22,'廣交會'!A:C,3,false) -> CF
A23: WU75947A4 | B23: Zeus Fighting | C23: 16 | D23: 13 | E23: 28 | F23: 18.6 | G23: PC | H23: 6 | I23: TOPLAND | J23: =VLOOKUP(A23,'廣交會'!A:C,3,false) -> CF
A24: WU75978A4 | B24: St. Michael With Sword And A Balance (Mbz+Color) | C24: 16 | D24: 14 | E24: 28 | F24: 19.5 | G24: PC | H24: 6 | I24: WU | J24: =VLOOKUP(A24,'廣交會'!A:C,3,false) -> CF
A25: WU76006A4 | B25: Archangel - St. Gabriel (Mbz+Color) | C25: 19 | D25: 15.5 | E25: 33 | F25: 18.8 | G25: PC | H25: 4 | I25: WU | J25: =VLOOKUP(A25,'廣交會'!A:C,3,false) -> CF
A26: WU76038A4 | B26: Roman Warrior With Spear And Shield | C26: 16.5 | D26: 11.5 | E26: 35.5 | F26: 18 | G26: PC | H26: 6 | I26: WU | J26: =VLOOKUP(A26,'廣交會'!A:C,3,false) -> CF
A27: WU76067A4 | B27: Yemaya - Mother Of All And Goddess Of The Ocean | C27: 19 | D27: 9 | E27: 27 | F27: 14 | G27: PC | H27: 6 | I27: WU | J27: =VLOOKUP(A27,'廣交會'!A:C,3,false) -> CF
A28: WU76149AA | B28: Innocence | C28: 8 | D28: 7.5 | E28: 21.5 | F28: 8.8 | G28: PC | H28: 18 | I28: GOV | J28: =VLOOKUP(A28,'廣交會'!A:C,3,false) -> CF
A29: WU76165AA | B29: Panda Cub Walking | C29: 13 | D29: 6.5 | E29: 7.5 | F29: 4.8 | G29: PC | H29: 36 | J29: =VLOOKUP(A29,'廣交會'!A:C,3,false) -> CF
A30: WU76198AA | B30: Black Bear Cub Standing Up | C30: 7 | D30: 6.5 | E30: 14.5 | F30: 3.8 | G30: PC | H30: 48 | I30: WU | J30: =VLOOKUP(A30,'廣交會'!A:C,3,false) -> CF
A31: WU76207A4 | B31: Jazz Band -Female Singer | C31: 10 | D31: 10 | E31: 31 | F31: 16.5 | G31: PC | H31: 6 | I31: WU | J31: =VLOOKUP(A31,'廣交會'!A:C,3,false) -> CF
A32: WU76209A4 | B32: Medusa | C32: 13 | D32: 11 | E32: 22 | F32: 12.5 | G32: PC | H32: 12 | J32: =VLOOKUP(A32,'廣交會'!A:C,3,false) -> CF
A33: WU76218A5 | B33: Jazz Band -Saxophone Player | C33: 11 | D33: 12.5 | E33: 29 | F33: 16.8 | G33: PC | H33: 6 | I33: WU | J33: =VLOOKUP(A33,'廣交會'!A:C,3,false) -> CF
A34: WU76220A5 | B34: Jazz Band -Clarinet Player | C34: 14.5 | D34: 11 | E34: 31 | F34: 16.8 | G34: PC | H34: 6 | J34: =VLOOKUP(A34,'廣交會'!A:C,3,false) -> CF
A35: WU76221A5 | B35: Jazz Band -Guitar Player | C35: 12 | D35: 10 | E35: 32.5 | F35: 17 | G35: PC | H35: 6 | J35: =VLOOKUP(A35,'廣交會'!A:C,3,false) -> CF
A36: WU76231A4 | B36: Achilles With Spear & Shield | C36: 20 | D36: 11 | E36: 29 | F36: 18.8 | G36: PC | H36: 4 | I36: WU | J36: =VLOOKUP(A36,'廣交會'!A:C,3,false) -> CF
A37: WU76232A4 | B37: Hector With Sword & Shield | C37: 23 | D37: 18.5 | E37: 29.5 | F37: 17.8 | G37: PC | H37: 4 | I37: WU | J37: =VLOOKUP(A37,'廣交會'!A:C,3,false) -> CF
A38: WU76268AB | B38: Archangel- St. Gabriel With Trumpet | C38: 6 | D38: 4 | E38: 11 | F38: 3.2 | G38: PC | H38: 48 | I38: WU | J38: =VLOOKUP(A38,'廣交會'!A:C,3,false) -> CF
A39: WU76279A4 | B39: Poseidon On Hippocampus Chariot | C39: 26 | D39: 12.5 | E39: 19 | F39: 22.5 | G39: PC | H39: 4 | J39: =VLOOKUP(A39,'廣交會'!A:C,3,false) -> CF
A40: WU76289AA | B40: Archangel- Uriel | C40: 6 | D40: 4 | E40: 11.5 | F40: 3.2 | G40: PC | H40: 72 | I40: WU | J40: =VLOOKUP(A40,'廣交會'!A:C,3,false) -> CF
...
